Workbook

Sheet datos_basicos
A1: Nombre | B1: Charth (Izzard) Dargson | C1: Raza | D1: Dragonborn | F1: Stats | I1: Niveles
A2: Clase | B2: Paladín | C2: Herencia | D2: Plata (Silver) | F2: Cód | G2: Modifier | H2: Final Score | I2: 0 | J2: B | K2: L1 | L2: L2 | M2: 4 | N2: 8 | O2: 12 | P2: 16 | Q2: 19 | R2: Extra
A3: Alineamiento | B3: Neutral / Bueno | C3: Edad | D3: 35 | F3: STR | G3: =floor(H3/2,1)-5 -> 3 | H3: =sum(I3:R3) -> 16 | I3: 2 | J3: 8 | K3: 5 | L3: 0 | N3: 1
A4: Peso | B4: 315lb / 143kg | C4: Altura | D4: 6.56ft / 2m | F4: DEX | G4: =floor(H4/2,1)-5 -> 0 | H4: =sum(I4:R4) -> 10 | I4: 0 | J4: 8 | K4: 2 | L4: 0
A5: Idiomas | B5: Común | C5: Draconiano | D5: Élfico | F5: CON | G5: =floor(H5/2,1)-5 -> 3 | H5: =sum(I5:R5) -> 16 | I5: 0 | J5: 8 | K5: 5 | L5: 2 | M5: 1
A6: Nivel | B6: 8 | C6: Proficiencia | D6: =CEILING(datos_basicos!B6/4,1)+1 -> 3 | F6: INT | G6: =floor(H6/2,1)-5 -> 2 | H6: =sum(I6:R6) -> 14 | I6: 0 | J6: 8 | K6: 4 | L6: 0 | R6: 2 | S6: Ioun de Intelecto
A7: Hit Dice (x Lvl) | B7: =concatenate(B6,"d10") -> 8d10 | C7: Velocidad (ft) | D7: 30 | F7: WIS | G7: =floor(H7/2,1)-5 -> 0 | H7: =sum(I7:R7) -> 10 | I7: 0 | J7: 8 | K7: 2 | L7: 0
A8: Iniciative (DEX) | B8: =G4 -> 0 | C8: Pass Percep (WIS) | D8: =G7 -> 0 | F8: CHA | G8: =floor(H8/2,1)-5 -> 2 | H8: =sum(I8:R8) -> 14 | I8: 1 | J8: 8 | K8: 5 | L8: 0 | P8: 0
A9: Proficiencia, Habilidades y tratos | J9: =sum(K3:K8)+2*sum(L3:L8) -> 27
A10: Weapons & Armors | B10: All armor, weapons and shields | C10: 0 | D10: None
A11: Attack Twice | B11: "Atacar" son dos ataques | C11: 5 | D11: None
A12: Blacksmith | B12: Puede hacer trabajos de Herrería | C12: 6 | D12: None
G14: # Spell slots | I14: Spell Level | N14: Max spell lvl to prepare | S14: Feats sugeridos para nivel 8:
I15: 1 | J15: 2 | K15: 3 | L15: 4 | M15: 5 | S15: Savage Attacker | T15: Once per turn when you roll damage for a melee weapon attack, you can reroll the weapon's damage dice and use either total.
G16: Character Level | H16: 1 | I16: 0 | J16: 0 | K16: 0 | L16: 0 | M16: 0 | N16: =ifna(HLOOKUP(0,{I16:M16;I$15:M$15},2,False),6)-1 -> 0 | S16: Skill Expert | T16: +1 in one ability, proficiency in one skill and expertise in one other in which you have proficiency (STR, History,Athletics)
H17: 2 | I17: 2 | J17: 0 | K17: 0 | L17: 0 | M17: 0 | N17: =ifna(HLOOKUP(0,{I17:M17;I$15:M$15},2,False),6)-1 -> 1 | S17: Heavy Armor Master | T17: +1 in Str. and bludgeoning, piercing, and slashing damage are reduced by 3 if you are wearing a heavy armor.
A18: Elementos usuales | H18: 3 | I18: 3 | J18: 0 | K18: 0 | L18: 0 | M18: 0 | N18: =ifna(HLOOKUP(0,{I18:M18;I$15:M$15},2,False),6)-1 -> 1 | S18: Slasher | T18: +1 in Str. or Dex., Per turn: reduce target's speed by 10 ft when you hit (slashing) and if critical target has disadvantage on attacks rolls.
A19: Activo (sin tilde las tiene Doby) | B19: Nombre | C19: Descripción | D19: tipo | H19: 5 | I19: 4 | J19: 2 | K19: 0 | L19: 0 | M19: 0 | N19: =ifna(HLOOKUP(0,{I19:M19;I$15:M$15},2,False),6)-1 -> 2 | S19: Tough | T19: Add twice your level to the hit point maximum formula.
A20: TRUE | B20: Rencorosa (Longsword) | D20: Arma | H20: 7 | I20: 4 | J20: 3 | K20: 0 | L20: 0 | M20: 0 | N20: =ifna(HLOOKUP(0,{I20:M20;I$15:M$15},2,False),6)-1 -> 2 | S20: Gift of the Metallic Dragon | T20: You can cast cure wounds (1/long rest). As a reaction to an attack, can manifest wings to get + Prof Bonus to your AC per day.
A21: FALSE | B21: Greatsword | D21: Arma | H21: 9 | I21: 4 | J21: 3 | K21: 2 | L21: 0 | M21: 0 | N21: =ifna(HLOOKUP(0,{I21:M21;I$15:M$15},2,False),6)-1 -> 3
A22: TRUE | B22: Maul (Martillo 2 manos) | D22: Arma | H22: 11 | I22: 4 | J22: 3 | K22: 3 | L22: 0 | M22: 0 | N22: =ifna(HLOOKUP(0,{I22:M22;I$15:M$15},2,False),6)-1 -> 3
A23: FALSE | B23: Jabalina Relámpago | D23: Arma | H23: 13 | I23: 4 | J23: 3 | K23: 3 | L23: 1 | M23: 0 | N23: =ifna(HLOOKUP(0,{I23:M23;I$15:M$15},2,False),6)-1 -> 4
A24: TRUE | B24: Cegadora (Greataxe) | D24: Arma | H24: 15 | I24: 4 | J24: 3 | K24: 3 | L24: 2 | M24: 0 | N24: =ifna(HLOOKUP(0,{I24:M24;I$15:M$15},2,False),6)-1 -> 4
A25: TRUE | B25: Unarmed Strike/Cuchillo | D25: Arma | H25: 17 | I25: 4 | J25: 3 | K25: 3 | L25: 3 | M25: 1 | N25: =ifna(HLOOKUP(0,{I25:M25;I$15:M$15},2,False),6)-1 -> 5
A26: TRUE | B26: Armadura completa c/cota de malla negra (adamantina) | C26: extra: inmune a crítico | D26: armadura | H26: 19 | I26: 4 | J26: 3 | K26: 3 | L26: 3 | M26: 2 | N26: =ifna(HLOOKUP(0,{I26:M26;I$15:M$15},2,False),6)-1 -> 5
A27: TRUE | B27: Escudo | C27: +2 en AC | D27: Armadura | G27: Number of Prepared Spells (CHA) | N27: =datos_basicos!G8+FLOOR(datos_basicos!B6/2,1) -> 6
A28: TRUE | B28: Defense (Fighting Style) | C28: +1 en AC | D28: Armadura
A29: TRUE | B29: 2 pociones de curación | D29: curación
A30: TRUE | B30: kit herbalismo | D30: curación
A31: TRUE | B31: Martillo de Phandelver | D31: Herrería
A32: TRUE | B32: Libros de armas | C32: Herrería, Herrería mágica y Planos de Jabalina eléctrica | D32: Herrería
A33: TRUE | B33: 2 lingotes negros | C33: Adamantina | D33: Herrería
A34: TRUE | B34: 1+5/6 lingotes plateados | C34: Mithril | D34: Herrería
A35: TRUE | B35: kit herrería | D35: Herrería
A36: TRUE | B36: Escamas de crías de dragón blanco | C36: Escamas antimágicas para herrería mágica | D36: Herrería
A37: TRUE | B37: 2 lingotes de acero | D37: Herrería
A38: TRUE | B38: 1 varilla metálica azul | D38: Herrería
A39: TRUE | B39: 5 cristales de fragua | C39: explosivos | D39: Herrería
A40: TRUE | B40: Ioun de Intelecto | C40: +2 INT y Codif. Pensamientos | D40: Magia
A41: TRUE | B41: Símbolo Sagrado | C41: collar canalizado en el escudo | D41: Magia
...

Sheet acciones_en_combate
A1: Ataques especiales y otras acciones
A2: Origen | B2: Nombre | C2: Descripción | D2: Obtenido en nivel | E2: Número de usos | F2: Tipo de Acción | G2: Alcance | H2: Recupera | I2: Ataque | J2: si es Success ST | K2: Daño (según nivel)
A3: De raza | B3: Breath Weapon | C3: Aliento frío | D3: 0 | E3: 1 | F3: Acción | G3: 15 ft. cone | H3: Short/Long Rest | I3: =8+datos_basicos!G5+datos_basicos!D6 -> 14 | J3: (CON) ST - Half damage | K3: =CONCATENATE(FLOOR(datos_basicos!B6/5,1)+2,"d6") -> 3d6
A4: De clase | B4: Divine Sense | C4: Olfato que huele maldad, Audición que escucha la bondad. Detect celestial, fiend, or undead not behind total cover, or the presence of place/object consecrated or desecrated, as with the hallow spell. | D4: 1 | E4: =1+datos_basicos!G8 -> 3 | F4: Acción | G4: 60ft | H4: Long Rest
A5: De clase | B5: Lay on Hands | C5: Restore hit points or use 5 hit points to cure disease or poison | D5: 1 | E5: =datos_basicos!B6*5 -> 40 | F5: Acción | G5: 0ft | H5: Long Rest
A6: Channel Divinity | B6: Abjure Enemy | C6: Holy Symbol frightens enemy. Fiends and undead in disadvantages | D6: 3 | E6: 1 | F6: Acción | G6: 60ft | H6: Short/Long Rest | I6: Frightened 1min: 0 speed | J6: (WIS) ST - Halved effect
A7: Channel Divinity | B7: Vow of Enmity | C7: Ventaja en tiradas de ataque contra el enemigo por un minuto o KO del enemigo | D7: 3 | E7: 1 | F7: Bonus | G7: 10ft | H7: Short/Long Rest
A8: Oath of Vengaence | B8: Relentless Avenger | C8: En una ataque de oportunidad efectivo, me puedo mover como parte de la acción | D8: 7 | E8: 1 vez por turno | F8: Reacción | G8: 15ft | H8: Sin descanso
A10: Fuerza | B10: =datos_basicos!G3 -> 3 | C10: Modificador de Ataque | D10: =datos_basicos!D6+datos_basicos!G3 -> 6 | E10: Cantidad de Ataques | F10: 2
A11: Tipos de ataque | B11: Tirada Ataque | C11: Daño (+ Fuerza) | D11: Tipo ataque | E11: Rango | F11: Extra
A12: Unarmed Strike/Cuchillo | B12: =concatenate("1d20+",$D$10) -> 1d20+6 | C12: =concatenate("1+",$B$10) -> 1+3 | D12: Bludgeoning/Piercing | E12: Melee
A13: Cuchillo | B13: =CONCATENATE("1d20+",$D$10) -> 1d20+6 | C13: =CONCATENATE("1+",$B$10) -> 1+3 | D13: Piercing | E13: Melee (lanzable)
A14: Dagger | B14: =CONCATENATE("1d20+",$D$10) -> 1d20+6 | C14: =CONCATENATE("1d4+",$B$10) -> 1d4+3 | D14: Piercing | E14: Melee (lanzable)
A15: Longsword | B15: =concatenate("1d20+",$D$10) -> 1d20+6 | C15: =concatenate("1d8+",$B$10) -> 1d8+3 | D15: Slashing | E15: Melee
A16: Greatsword | B16: =concatenate("1d20+",$D$10) -> 1d20+6 | C16: =concatenate("2d6+",$B$10) -> 2d6+3 | D16: Slashing | E16: Melee
A17: Maul (Martillo 2 manos) | B17: =concatenate("1d20+",$D$10) -> 1d20+6 | C17: =concatenate("2d6+",$B$10) -> 2d6+3 | D17: Bludgeoning | E17: Melee
A18: Cegadora (Greataxe) | B18: =concatenate("1d20+",$D$10) -> 1d20+6 | C18: =concatenate("1d12+3+",$B$10) -> 1d12+3+3 | D18: Slashing | E18: Melee | F18: Lo que mata no se puede revivir. 2do ataque en turno con desventaja
A19: Rencorosa (Longsword) | B19: =concatenate("1d20+2+",$D$10) -> 1d20+2+6 | C19: =concatenate("1d8+2+",$B$10) -> 1d8+2+3 | D19: Slashing | E19: Melee | F19: Daño extra (#fallos)d4. Extensible a 10ft después de fallo
A20: Jabalina | B20: =concatenate("1d20+",$D$10) -> 1d20+6 | C20: =concatenate("1d6+",$B$10) -> 1d6+3 | D20: Piercing | E20: Melee (lanzable)
A21: Jabalína Relámpago | B21: =concatenate("1d20+",$D$10) -> 1d20+6 | C21: =concatenate("1d6+",$B$10) -> 1d6+3 | D21: Piercing, Lightning | E21: Melee (lanzable) | F21: Jabalina con daño de electricidad. Hace un trueno al ser lanzada
A22: Jabalina Electrica fallada | B22: =concatenate("1d20+",$D$10) -> 1d20+6 | C22: =concatenate("1d6+",$B$10) -> 1d6+3 | D22: Piercing, Lightning | E22: Melee (lanzable) | F22: saca chispas al querer activarla
A23: Atlatl | F23: Duplica lanzamiento de Jabalina
A24: Ballesta | B24: =concatenate("1d20+",$D$10) -> 1d20+6 | C24: =concatenate("1d6+",$B$10) -> 1d6+3 | D24: Piercing | E24: Rango
A26: Charisma | B26: =datos_basicos!G8 -> 2 | C26: Spell Attack Modifier | D26: =datos_basicos!D6+datos_basicos!G8 -> 5 | E26: Spell save DC | F26: =8+datos_basicos!D6+datos_basicos!G8 -> 13
A27: Always Ready Spells | B27: Description | C27: Character Level | D27: Spell Level | E27: Damage | F27: Extra
A28: Divine Smite | B28: Extra Radiant Damage when you hit melee | C28: 2 | D28: 1 | E28: min(5,Spell Lvl+1)d8 | F28: +1d8 if undead
A29: Bane | C29: 3
A30: Hunter's Mark | C30: 3
A31: Hold Person | C31: 5
A32: Misty Step | C32: 5
A33: Haste | C33: 9
A34: Protection from energy | C34: 9
A35: Banishment | C35: 13
A36: Dimension Floor | C36: 13
A37: Hold monster | C37: 17
A38: Scrying | C38: 17
A39: =concatenate("Chosen Spells (",datos_basicos!N27,")") -> Chosen Spells (6) | B39: Spell Level | C39: Casting Time | D39: Range | E39: Damage | F39: Duration
A40: Bless | B40: =VLOOKUP($A40,spells_list!$B$2:$H$55,COLUMN(),False) -> 1 | C40: =VLOOKUP($A40,spells_list!$B$2:$H$55,COLUMN(),False) -> 1 Action | D40: =VLOOKUP($A40,spells_list!$B$2:$H$55,COLUMN(),False) -> 30 feet | E40: =VLOOKUP($A40,spells_list!$B$2:$H$55,COLUMN(),False) | F40: =VLOOKUP($A40,spells_list!$B$2:$H$55,COLUMN(),False) -> Concentration, up to 1 minute
A41: DIvine Favor | B41: =VLOOKUP($A41,spells_list!$B$2:$H$55,COLUMN(),False) -> 1 | C41: =VLOOKUP($A41,spells_list!$B$2:$H$55,COLUMN(),False) -> 1 Bonus Action | D41: =VLOOKUP($A41,spells_list!$B$2:$H$55,COLUMN(),False) -> Self | E41: =VLOOKUP($A41,spells_list!$B$2:$H$55,COLUMN(),False) | F41: =VLOOKUP($A41,spells_list!$B$2:$H$55,COLUMN(),False) -> Concentration, up to 1 minute
A42: Thunderous Smite | B42: =VLOOKUP($A42,spells_list!$B$2:$H$55,COLUMN(),False) -> 1 | C42: =VLOOKUP($A42,spells_list!$B$2:$H$55,COLUMN(),False) -> 1 Bonus Action | D42: =VLOOKUP($A42,spells_list!$B$2:$H$55,COLUMN(),False) -> Self | E42: =VLOOKUP($A42,spells_list!$B$2:$H$55,COLUMN(),False) | F42: =VLOOKUP($A42,spells_list!$B$2:$H$55,COLUMN(),False) -> Concentration, up to 1 minute
...

Sheet spells_list
A1: Prepared | B1: Spell Name | C1: Level | D1: Casting Time | E1: Range | F1: Description | G1: Duration | H1: Components | I1: School
A2: FALSE | B2: Bless | C2: 1 | D2: 1 Action | E2: 30 feet | G2: Concentration, up to 1 minute | H2: V, S, M | I2: Enchantment
A3: FALSE | B3: Ceremony | C3: 1 | D3: 1 Action R | E3: Touch | G3: Instantaneous | H3: V, S, M | I3: Evocation
A4: FALSE | B4: Command | C4: 1 | D4: 1 Action | E4: 60 feet | G4: 1 round | H4: V | I4: Enchantment
A5: TRUE | B5: Compelled Duel | C5: 1 | D5: 1 Bonus Action | E5: 30 feet | G5: Concentration, up to 1 minute | H5: V | I5: Enchantment
A6: FALSE | B6: Cure Wounds | C6: 1 | D6: 1 Action | E6: Touch | G6: Instantaneous | H6: V, S | I6: Evocation
A7: FALSE | B7: Detect Evil and Good | C7: 1 | D7: 1 Action | E7: Self | G7: Concentration, up to 10 minutes | H7: V, S | I7: Divination
A8: FALSE | B8: Detect Magic | C8: 1 | D8: 1 Action R | E8: Self | G8: Concentration, up to 10 minutes | H8: V, S | I8: Divination
A9: FALSE | B9: Detect Poison and Disease | C9: 1 | D9: 1 Action | E9: Self | G9: Concentration, up to 10 minutes | H9: V, S, M | I9: Divination
A10: TRUE | B10: Divine Favor | C10: 1 | D10: 1 Bonus Action | E10: Self | G10: Concentration, up to 1 minute | H10: V, S | I10: Evocation
A11: FALSE | B11: Heroism | C11: 1 | D11: 1 Action | E11: Touch | G11: Concentration, up to 1 minute | H11: V, S | I11: Enchantment
A12: FALSE | B12: Protection from Evil and Good | C12: 1 | D12: 1 Action | E12: Touch | G12: Concentration, up to 10 minutes | H12: V, S, M | I12: Abjuration
A13: FALSE | B13: Purify Food and Drink | C13: 1 | D13: 1 Action R | E13: 10 feet | G13: Instantaneous | H13: V, S | I13: Transmutation
... A55: FALSE | B55: Summon Celestial | C55: 5 | D55: 1 Action | E55: 90 feet | G55: Concentration, up to 1 hour | H55: V, S, M | I55: Conjuration

Sheet status
A1: Hit Points | C1: Breath Weapon | D1: Reencorosa | E1: Lay on Hands | F1: Spell Slot Lvl | G1: # Spell Lvl1 | H1: # Spell Lvl2 | I1: # Spell Lvl3 | J1: # Spell Lvl4 | K1: # Spell Lvl5
A2: =4+datos_basicos!B6*(6+datos_basicos!G5)-A3 -> 65 | B2: =CONCAT("de ",4+datos_basicos!B6*(6+datos_basicos!G5)) -> de 76 | C2: Usado? | D2: =CONCAT(D3,"d4") -> 0d4 | E2: =acciones_en_combate!E5-E3 -> 0 | F2: =IFERROR(__xludf.DUMMYFUNCTION("max(filter(datos_basicos!H16:H26,datos_basicos!H16:H26<datos_basicos!B6))"),7.0) -> 7 | G2: =VLOOKUP(F2,datos_basicos!H16:Q26,2)-G3 -> 1 | H2: =VLOOKUP(F2,datos_basicos!H16:Q26,3)-H3 -> 1 | I2: =VLOOKUP(F2,datos_basicos!H16:Q26,4)-I3 -> 0 | J2: =VLOOKUP(F2,datos_basicos!H16:Q26,5)-J3 -> 0 | K2: =VLOOKUP(F2,datos_basicos!H16:Q26,6)-K3 -> 0
A3: =11 -> 11 | B3: Hit Points Dyn | C3: FALSE | D3: 0 | E3: =10+25+5 -> 40 | F3: Usados | G3: 3 | H3: 2
A5: Armadura | C5: AC | D5: =10+datos_basicos!G4+SUMPRODUCT(C7:C12,D7:D12) -> 21 | E5: Arma
A6: =CONCAT(A5," Disponibles") -> Armadura Disponibles | B6: Descripción | C6: AC | D6: Activo | E6: =IFERROR(__xludf.DUMMYFUNCTION("filter(E8:E28,F8:F28)"),"Rencorosa (Longsword)") -> Rencorosa (Longsword) | F6: Activa | G6: =VLOOKUP(E6,E8:K28,3,0) -> 1d20+2+6 | H6: =VLOOKUP(E6,E8:K28,4,0) -> 1d8+2+3 | I6: =VLOOKUP(E6,E8:K28,5,0) -> Slashing | J6: =VLOOKUP(E6,E8:K28,6,0) -> Melee | K6: =VLOOKUP(E6,E8:K28,7,0) -> Daño extra (#fallos)d4. Extensible a 10ft después de fallo
A7: =IFERROR(__xludf.DUMMYFUNCTION("FILTER(datos_basicos!$B$20:$C$70,datos_basicos!$A$20:$A$70,datos_basicos!$D$20:$D$70 = ""Armadura"")"),"Armadura completa c/cota de malla negra (adamantina)") -> Armadura completa c/cota de malla negra (adamantina) | B7: =IFERROR(__xludf.DUMMYFUNCTION("""COMPUTED_VALUE"""),"extra: inmune a crítico") -> extra: inmune a crítico | C7: 8 | D7: TRUE | E7: =CONCAT(E5," Disponibles") -> Arma Disponibles | F7: Activo | G7: Tirada Ataque | H7: Daño (+ Fuerza) | I7: Tipo ataque | J7: Rango | K7: Extra
A8: =IFERROR(__xludf.DUMMYFUNCTION("""COMPUTED_VALUE"""),"Escudo") -> Escudo | B8: =IFERROR(__xludf.DUMMYFUNCTION("""COMPUTED_VALUE"""),"+2 en AC") -> +2 en AC | C8: =2 -> 2 | D8: TRUE | E8: =IFERROR(__xludf.DUMMYFUNCTION("FILTER(datos_basicos!$B$20:$B$70,datos_basicos!$A$20:$A$70,datos_basicos!$D$20:$D$70 = E5)"),"Rencorosa (Longsword)") -> Rencorosa (Longsword) | F8: TRUE | G8: {=ifna(index(acciones_en_combate!$A$11:$F$24,MATCH($E8, acciones_en_combate!$A$11:$A$24, 0),MATCH(G$7, acciones_en_combate!B$11:B$24, 0)+1),"")} -> 1d20+2+6 | H8: {=ifna(index(acciones_en_combate!$A$11:$F$24,MATCH($E8, acciones_en_combate!$A$11:$A$24, 0),MATCH(H$7, acciones_en_combate!C$11:C$24, 0)+2),"")} -> 1d8+2+3 | I8: {=ifna(index(acciones_en_combate!$A$11:$F$24,MATCH($E8, acciones_en_combate!$A$11:$A$24, 0),MATCH(I$7, acciones_en_combate!D$11:D$24, 0)+3),"")} -> Slashing | J8: {=ifna(index(acciones_en_combate!$A$11:$F$24,MATCH($E8, acciones_en_combate!$A$11:$A$24, 0),MATCH(J$7, acciones_en_combate!E$11:E$24, 0)+4),"")} -> Melee | K8: {=ifna(index(acciones_en_combate!$A$11:$F$24,MATCH($E8, acciones_en_combate!$A$11:$A$24, 0),MATCH(K$7, acciones_en_combate!F$11:F$24, 0)+5),"")} -> Daño extra (#fallos)d4. Extensible a 10ft después de fallo
A9: =IFERROR(__xludf.DUMMYFUNCTION("""COMPUTED_VALUE"""),"Defense (Fighting Style)") -> Defense (Fighting Style) | B9: =IFERROR(__xludf.DUMMYFUNCTION("""COMPUTED_VALUE"""),"+1 en AC") -> +1 en AC | C9: 1 | D9: TRUE | E9: =IFERROR(__xludf.DUMMYFUNCTION("""COMPUTED_VALUE"""),"Maul (Martillo 2 manos)") -> Maul (Martillo 2 manos) | F9: FALSE | G9: {=ifna(index(acciones_en_combate!$A$11:$F$24,MATCH($E9, acciones_en_combate!$A$11:$A$24, 0),MATCH(G$7, acciones_en_combate!B$11:B$24, 0)+1),"")} -> 1d20+6 | H9: {=ifna(index(acciones_en_combate!$A$11:$F$24,MATCH($E9, acciones_en_combate!$A$11:$A$24, 0),MATCH(H$7, acciones_en_combate!C$11:C$24, 0)+2),"")} -> 2d6+3 | I9: {=ifna(index(acciones_en_combate!$A$11:$F$24,MATCH($E9, acciones_en_combate!$A$11:$A$24, 0),MATCH(I$7, acciones_en_combate!D$11:D$24, 0)+3),"")} -> Bludgeoning | J9: {=ifna(index(acciones_en_combate!$A$11:$F$24,MATCH($E9, acciones_en_combate!$A$11:$A$24, 0),MATCH(J$7, acciones_en_combate!E$11:E$24, 0)+4),"")} -> Melee | K9: {=ifna(index(acciones_en_combate!$A$11:$F$24,MATCH($E9, acciones_en_combate!$A$11:$A$24, 0),MATCH(K$7, acciones_en_combate!F$11:F$24, 0)+5),"")}
D10: FALSE | E10: =IFERROR(__xludf.DUMMYFUNCTION("""COMPUTED_VALUE"""),"Cegadora (Greataxe)") -> Cegadora (Greataxe) | F10: FALSE | G10: {=ifna(index(acciones_en_combate!$A$11:$F$24,MATCH($E10, acciones_en_combate!$A$11:$A$24, 0),MATCH(G$7, acciones_en_combate!B$11:B$24, 0)+1),"")} -> 1d20+6 | H10: {=ifna(index(acciones_en_combate!$A$11:$F$24,MATCH($E10, acciones_en_combate!$A$11:$A$24, 0),MATCH(H$7, acciones_en_combate!C$11:C$24, 0)+2),"")} -> 1d12+3+3 | I10: {=ifna(index(acciones_en_combate!$A$11:$F$24,MATCH($E10, acciones_en_combate!$A$11:$A$24, 0),MATCH(I$7, acciones_en_combate!D$11:D$24, 0)+3),"")} -> Slashing | J10: {=ifna(index(acciones_en_combate!$A$11:$F$24,MATCH($E10, acciones_en_combate!$A$11:$A$24, 0),MATCH(J$7, acciones_en_combate!E$11:E$24, 0)+4),"")} -> Melee | K10: {=ifna(index(acciones_en_combate!$A$11:$F$24,MATCH($E10, acciones_en_combate!$A$11:$A$24, 0),MATCH(K$7, acciones_en_combate!F$11:F$24, 0)+5),"")} -> Lo que mata no se puede revivir. 2do ataque en turno con desventaja
D11: FALSE | E11: =IFERROR(__xludf.DUMMYFUNCTION("""COMPUTED_VALUE"""),"Unarmed Strike/Cuchillo") -> Unarmed Strike/Cuchillo | F11: FALSE | G11: {=ifna(index(acciones_en_combate!$A$11:$F$24,MATCH($E11, acciones_en_combate!$A$11:$A$24, 0),MATCH(G$7, acciones_en_combate!B$11:B$24, 0)+1),"")} -> 1d20+6 | H11: {=ifna(index(acciones_en_combate!$A$11:$F$24,MATCH($E11, acciones_en_combate!$A$11:$A$24, 0),MATCH(H$7, acciones_en_combate!C$11:C$24, 0)+2),"")} -> 1+3 | I11: {=ifna(index(acciones_en_combate!$A$11:$F$24,MATCH($E11, acciones_en_combate!$A$11:$A$24, 0),MATCH(I$7, acciones_en_combate!D$11:D$24, 0)+3),"")} -> Bludgeoning/Piercing | J11: {=ifna(index(acciones_en_combate!$A$11:$F$24,MATCH($E11, acciones_en_combate!$A$11:$A$24, 0),MATCH(J$7, acciones_en_combate!E$11:E$24, 0)+4),"")} -> Melee | K11: {=ifna(index(acciones_en_combate!$A$11:$F$24,MATCH($E11, acciones_en_combate!$A$11:$A$24, 0),MATCH(K$7, acciones_en_combate!F$11:F$24, 0)+5),"")}
D12: FALSE | E12: =IFERROR(__xludf.DUMMYFUNCTION("""COMPUTED_VALUE"""),"Jabalina Electrica fallada") -> Jabalina Electrica fallada | F12: FALSE | G12: {=ifna(index(acciones_en_combate!$A$11:$F$24,MATCH($E12, acciones_en_combate!$A$11:$A$24, 0),MATCH(G$7, acciones_en_combate!B$11:B$24, 0)+1),"")} -> 1d20+6 | H12: {=ifna(index(acciones_en_combate!$A$11:$F$24,MATCH($E12, acciones_en_combate!$A$11:$A$24, 0),MATCH(H$7, acciones_en_combate!C$11:C$24, 0)+2),"")} -> 1d6+3 | I12: {=ifna(index(acciones_en_combate!$A$11:$F$24,MATCH($E12, acciones_en_combate!$A$11:$A$24, 0),MATCH(I$7, acciones_en_combate!D$11:D$24, 0)+3),"")} -> Piercing, Lightning | J12: {=ifna(index(acciones_en_combate!$A$11:$F$24,MATCH($E12, acciones_en_combate!$A$11:$A$24, 0),MATCH(J$7, acciones_en_combate!E$11:E$24, 0)+4),"")} -> Melee (lanzable) | K12: {=ifna(index(acciones_en_combate!$A$11:$F$24,MATCH($E12, acciones_en_combate!$A$11:$A$24, 0),MATCH(K$7, acciones_en_combate!F$11:F$24, 0)+5),"")} -> saca chispas al querer activarla
A13: Siempre Activo | C13: Nombre | D13: Desde nivel | E13: =IFERROR(__xludf.DUMMYFUNCTION("""COMPUTED_VALUE"""),"Atlatl") -> Atlatl | F13: FALSE | G13: {=ifna(index(acciones_en_combate!$A$11:$F$24,MATCH($E13, acciones_en_combate!$A$11:$A$24, 0),MATCH(G$7, acciones_en_combate!B$11:B$24, 0)+1),"")} | H13: {=ifna(index(acciones_en_combate!$A$11:$F$24,MATCH($E13, acciones_en_combate!$A$11:$A$24, 0),MATCH(H$7, acciones_en_combate!C$11:C$24, 0)+2),"")} | I13: {=ifna(index(acciones_en_combate!$A$11:$F$24,MATCH($E13, acciones_en_combate!$A$11:$A$24, 0),MATCH(I$7, acciones_en_combate!D$11:D$24, 0)+3),"")} | J13: {=ifna(index(acciones_en_combate!$A$11:$F$24,MATCH($E13, acciones_en_combate!$A$11:$A$24, 0),MATCH(J$7, acciones_en_combate!E$11:E$24, 0)+4),"")} | K13: {=ifna(index(acciones_en_combate!$A$11:$F$24,MATCH($E13, acciones_en_combate!$A$11:$A$24, 0),MATCH(K$7, acciones_en_combate!F$11:F$24, 0)+5),"")} -> Duplica lanzamiento de Jabalina
A14: Resistencia al Frío | C14: Race trait | D14: 0 | F14: FALSE | G14: {=ifna(index(acciones_en_combate!$A$11:$F$24,MATCH($E14, acciones_en_combate!$A$11:$A$24, 0),MATCH(G$7, acciones_en_combate!B$11:B$24, 0)+1),"")} | H14: {=ifna(index(acciones_en_combate!$A$11:$F$24,MATCH($E14, acciones_en_combate!$A$11:$A$24, 0),MATCH(H$7, acciones_en_combate!C$11:C$24, 0)+2),"")} | I14: {=ifna(index(acciones_en_combate!$A$11:$F$24,MATCH($E14, acciones_en_combate!$A$11:$A$24, 0),MATCH(I$7, acciones_en_combate!D$11:D$24, 0)+3),"")} | J14: {=ifna(index(acciones_en_combate!$A$11:$F$24,MATCH($E14, acciones_en_combate!$A$11:$A$24, 0),MATCH(J$7, acciones_en_combate!E$11:E$24, 0)+4),"")} | K14: {=ifna(index(acciones_en_combate!$A$11:$F$24,MATCH($E14, acciones_en_combate!$A$11:$A$24, 0),MATCH(K$7, acciones_en_combate!F$11:F$24, 0)+5),"")}
A15: -3 for bludgeoning, piercing, slashing damage with heavy armor. | C15: Heavy Armor Master | D15: 8 | F15: FALSE | G15: {=ifna(index(acciones_en_combate!$A$11:$F$24,MATCH($E15, acciones_en_combate!$A$11:$A$24, 0),MATCH(G$7, acciones_en_combate!B$11:B$24, 0)+1),"")} | H15: {=ifna(index(acciones_en_combate!$A$11:$F$24,MATCH($E15, acciones_en_combate!$A$11:$A$24, 0),MATCH(H$7, acciones_en_combate!C$11:C$24, 0)+2),"")} | I15: {=ifna(index(acciones_en_combate!$A$11:$F$24,MATCH($E15, acciones_en_combate!$A$11:$A$24, 0),MATCH(I$7, acciones_en_combate!D$11:D$24, 0)+3),"")} | J15: {=ifna(index(acciones_en_combate!$A$11:$F$24,MATCH($E15, acciones_en_combate!$A$11:$A$24, 0),MATCH(J$7, acciones_en_combate!E$11:E$24, 0)+4),"")} | K15: {=ifna(index(acciones_en_combate!$A$11:$F$24,MATCH($E15, acciones_en_combate!$A$11:$A$24, 0),MATCH(K$7, acciones_en_combate!F$11:F$24, 0)+5),"")}
A16: Inmune to disease | C16: Divine Health | D16: 3 | F16: FALSE | G16: {=ifna(index(acciones_en_combate!$A$11:$F$24,MATCH($E16, acciones_en_combate!$A$11:$A$24, 0),MATCH(G$7, acciones_en_combate!B$11:B$24, 0)+1),"")} | H16: {=ifna(index(acciones_en_combate!$A$11:$F$24,MATCH($E16, acciones_en_combate!$A$11:$A$24, 0),MATCH(H$7, acciones_en_combate!C$11:C$24, 0)+2),"")} | I16: {=ifna(index(acciones_en_combate!$A$11:$F$24,MATCH($E16, acciones_en_combate!$A$11:$A$24, 0),MATCH(I$7, acciones_en_combate!D$11:D$24, 0)+3),"")} | J16: {=ifna(index(acciones_en_combate!$A$11:$F$24,MATCH($E16, acciones_en_combate!$A$11:$A$24, 0),MATCH(J$7, acciones_en_combate!E$11:E$24, 0)+4),"")} | K16: {=ifna(index(acciones_en_combate!$A$11:$F$24,MATCH($E16, acciones_en_combate!$A$11:$A$24, 0),MATCH(K$7, acciones_en_combate!F$11:F$24, 0)+5),"")}
A17: Desventaja en sigilo | C17: Armadura pesada | D17: 0 | F17: FALSE | G17: {=ifna(index(acciones_en_combate!$A$11:$F$24,MATCH($E17, acciones_en_combate!$A$11:$A$24, 0),MATCH(G$7, acciones_en_combate!B$11:B$24, 0)+1),"")} | H17: {=ifna(index(acciones_en_combate!$A$11:$F$24,MATCH($E17, acciones_en_combate!$A$11:$A$24, 0),MATCH(H$7, acciones_en_combate!C$11:C$24, 0)+2),"")} | I17: {=ifna(index(acciones_en_combate!$A$11:$F$24,MATCH($E17, acciones_en_combate!$A$11:$A$24, 0),MATCH(I$7, acciones_en_combate!D$11:D$24, 0)+3),"")} | J17: {=ifna(index(acciones_en_combate!$A$11:$F$24,MATCH($E17, acciones_en_combate!$A$11:$A$24, 0),MATCH(J$7, acciones_en_combate!E$11:E$24, 0)+4),"")} | K17: {=ifna(index(acciones_en_combate!$A$11:$F$24,MATCH($E17, acciones_en_combate!$A$11:$A$24, 0),MATCH(K$7, acciones_en_combate!F$11:F$24, 0)+5),"")}
A18: ST de Aliade a 10ft + CHA bonus | C18: Aura of Protection | D18: 6 | F18: FALSE | G18: {=ifna(index(acciones_en_combate!$A$11:$F$24,MATCH($E18, acciones_en_combate!$A$11:$A$24, 0),MATCH(G$7, acciones_en_combate!B$11:B$24, 0)+1),"")} | H18: {=ifna(index(acciones_en_combate!$A$11:$F$24,MATCH($E18, acciones_en_combate!$A$11:$A$24, 0),MATCH(H$7, acciones_en_combate!C$11:C$24, 0)+2),"")} | I18: {=ifna(index(acciones_en_combate!$A$11:$F$24,MATCH($E18, acciones_en_combate!$A$11:$A$24, 0),MATCH(I$7, acciones_en_combate!D$11:D$24, 0)+3),"")} | J18: {=ifna(index(acciones_en_combate!$A$11:$F$24,MATCH($E18, acciones_en_combate!$A$11:$A$24, 0),MATCH(J$7, acciones_en_combate!E$11:E$24, 0)+4),"")} | K18: {=ifna(index(acciones_en_combate!$A$11:$F$24,MATCH($E18, acciones_en_combate!$A$11:$A$24, 0),MATCH(K$7, acciones_en_combate!F$11:F$24, 0)+5),"")}
A19: Saving Throw | D19: Proficient | F19: FALSE | G19: {=ifna(index(acciones_en_combate!$A$11:$F$24,MATCH($E19, acciones_en_combate!$A$11:$A$24, 0),MATCH(G$7, acciones_en_combate!B$11:B$24, 0)+1),"")} | H19: {=ifna(index(acciones_en_combate!$A$11:$F$24,MATCH($E19, acciones_en_combate!$A$11:$A$24, 0),MATCH(H$7, acciones_en_combate!C$11:C$24, 0)+2),"")} | I19: {=ifna(index(acciones_en_combate!$A$11:$F$24,MATCH($E19, acciones_en_combate!$A$11:$A$24, 0),MATCH(I$7, acciones_en_combate!D$11:D$24, 0)+3),"")} | J19: {=ifna(index(acciones_en_combate!$A$11:$F$24,MATCH($E19, acciones_en_combate!$A$11:$A$24, 0),MATCH(J$7, acciones_en_combate!E$11:E$24, 0)+4),"")} | K19: {=ifna(index(acciones_en_combate!$A$11:$F$24,MATCH($E19, acciones_en_combate!$A$11:$A$24, 0),MATCH(K$7, acciones_en_combate!F$11:F$24, 0)+5),"")}
A20: Athletics | B20: STR | C20: =datos_basicos!G3+datos_basicos!$D$6*D20 -> 6 | D20: TRUE | F20: FALSE | G20: {=ifna(index(acciones_en_combate!$A$11:$F$24,MATCH($E20, acciones_en_combate!$A$11:$A$24, 0),MATCH(G$7, acciones_en_combate!B$11:B$24, 0)+1),"")} | H20: {=ifna(index(acciones_en_combate!$A$11:$F$24,MATCH($E20, acciones_en_combate!$A$11:$A$24, 0),MATCH(H$7, acciones_en_combate!C$11:C$24, 0)+2),"")} | I20: {=ifna(index(acciones_en_combate!$A$11:$F$24,MATCH($E20, acciones_en_combate!$A$11:$A$24, 0),MATCH(I$7, acciones_en_combate!D$11:D$24, 0)+3),"")} | J20: {=ifna(index(acciones_en_combate!$A$11:$F$24,MATCH($E20, acciones_en_combate!$A$11:$A$24, 0),MATCH(J$7, acciones_en_combate!E$11:E$24, 0)+4),"")} | K20: {=ifna(index(acciones_en_combate!$A$11:$F$24,MATCH($E20, acciones_en_combate!$A$11:$A$24, 0),MATCH(K$7, acciones_en_combate!F$11:F$24, 0)+5),"")}
A21: Religion | B21: INT | C21: =datos_basicos!G6+datos_basicos!$D$6*D20 -> 5 | D21: TRUE | F21: FALSE | G21: {=ifna(index(acciones_en_combate!$A$11:$F$24,MATCH($E21, acciones_en_combate!$A$11:$A$24, 0),MATCH(G$7, acciones_en_combate!B$11:B$24, 0)+1),"")} | H21: {=ifna(index(acciones_en_combate!$A$11:$F$24,MATCH($E21, acciones_en_combate!$A$11:$A$24, 0),MATCH(H$7, acciones_en_combate!C$11:C$24, 0)+2),"")} | I21: {=ifna(index(acciones_en_combate!$A$11:$F$24,MATCH($E21, acciones_en_combate!$A$11:$A$24, 0),MATCH(I$7, acciones_en_combate!D$11:D$24, 0)+3),"")} | J21: {=ifna(index(acciones_en_combate!$A$11:$F$24,MATCH($E21, acciones_en_combate!$A$11:$A$24, 0),MATCH(J$7, acciones_en_combate!E$11:E$24, 0)+4),"")} | K21: {=ifna(index(acciones_en_combate!$A$11:$F$24,MATCH($E21, acciones_en_combate!$A$11:$A$24, 0),MATCH(K$7, acciones_en_combate!F$11:F$24, 0)+5),"")}
A22: Medicine | B22: WIS | C22: 3 | D22: TRUE | F22: FALSE | G22: {=ifna(index(acciones_en_combate!$A$11:$F$24,MATCH($E22, acciones_en_combate!$A$11:$A$24, 0),MATCH(G$7, acciones_en_combate!B$11:B$24, 0)+1),"")} | H22: {=ifna(index(acciones_en_combate!$A$11:$F$24,MATCH($E22, acciones_en_combate!$A$11:$A$24, 0),MATCH(H$7, acciones_en_combate!C$11:C$24, 0)+2),"")} | I22: {=ifna(index(acciones_en_combate!$A$11:$F$24,MATCH($E22, acciones_en_combate!$A$11:$A$24, 0),MATCH(I$7, acciones_en_combate!D$11:D$24, 0)+3),"")} | J22: {=ifna(index(acciones_en_combate!$A$11:$F$24,MATCH($E22, acciones_en_combate!$A$11:$A$24, 0),MATCH(J$7, acciones_en_combate!E$11:E$24, 0)+4),"")} | K22: {=ifna(index(acciones_en_combate!$A$11:$F$24,MATCH($E22, acciones_en_combate!$A$11:$A$24, 0),MATCH(K$7, acciones_en_combate!F$11:F$24, 0)+5),"")}
A23: Intimidation | B23: CHA | C23: 4 | D23: TRUE | F23: FALSE | G23: {=ifna(index(acciones_en_combate!$A$11:$F$24,MATCH($E23, acciones_en_combate!$A$11:$A$24, 0),MATCH(G$7, acciones_en_combate!B$11:B$24, 0)+1),"")} | H23: {=ifna(index(acciones_en_combate!$A$11:$F$24,MATCH($E23, acciones_en_combate!$A$11:$A$24, 0),MATCH(H$7, acciones_en_combate!C$11:C$24, 0)+2),"")} | I23: {=ifna(index(acciones_en_combate!$A$11:$F$24,MATCH($E23, acciones_en_combate!$A$11:$A$24, 0),MATCH(I$7, acciones_en_combate!D$11:D$24, 0)+3),"")} | J23: {=ifna(index(acciones_en_combate!$A$11:$F$24,MATCH($E23, acciones_en_combate!$A$11:$A$24, 0),MATCH(J$7, acciones_en_combate!E$11:E$24, 0)+4),"")} | K23: {=ifna(index(acciones_en_combate!$A$11:$F$24,MATCH($E23, acciones_en_combate!$A$11:$A$24, 0),MATCH(K$7, acciones_en_combate!F$11:F$24, 0)+5),"")}
A24: Thousand Year War (Dragons vs GIants) | B24: INT | C24: 5 | D24: TRUE | F24: FALSE
A25: Saving Throw | B25: STR | C25: =datos_basicos!G3+datos_basicos!$D$6*D25 -> 3 | D25: FALSE | F25: FALSE | G25: {=ifna(index(acciones_en_combate!$A$11:$F$24,MATCH($E25, acciones_en_combate!$A$11:$A$24, 0),MATCH(G$7, acciones_en_combate!B$11:B$24, 0)+1),"")} | H25: {=ifna(index(acciones_en_combate!$A$11:$F$24,MATCH($E25, acciones_en_combate!$A$11:$A$24, 0),MATCH(H$7, acciones_en_combate!C$11:C$24, 0)+2),"")} | I25: {=ifna(index(acciones_en_combate!$A$11:$F$24,MATCH($E25, acciones_en_combate!$A$11:$A$24, 0),MATCH(I$7, acciones_en_combate!D$11:D$24, 0)+3),"")} | J25: {=ifna(index(acciones_en_combate!$A$11:$F$24,MATCH($E25, acciones_en_combate!$A$11:$A$24, 0),MATCH(J$7, acciones_en_combate!E$11:E$24, 0)+4),"")} | K25: {=ifna(index(acciones_en_combate!$A$11:$F$24,MATCH($E25, acciones_en_combate!$A$11:$A$24, 0),MATCH(K$7, acciones_en_combate!F$11:F$24, 0)+5),"")}
A26: Saving Throw | B26: DEX | C26: =datos_basicos!G4+datos_basicos!$D$6*D26 -> 0 | D26: FALSE | F26: FALSE | G26: {=ifna(index(acciones_en_combate!$A$11:$F$24,MATCH($E26, acciones_en_combate!$A$11:$A$24, 0),MATCH(G$7, acciones_en_combate!B$11:B$24, 0)+1),"")} | H26: {=ifna(index(acciones_en_combate!$A$11:$F$24,MATCH($E26, acciones_en_combate!$A$11:$A$24, 0),MATCH(H$7, acciones_en_combate!C$11:C$24, 0)+2),"")} | I26: {=ifna(index(acciones_en_combate!$A$11:$F$24,MATCH($E26, acciones_en_combate!$A$11:$A$24, 0),MATCH(I$7, acciones_en_combate!D$11:D$24, 0)+3),"")} | J26: {=ifna(index(acciones_en_combate!$A$11:$F$24,MATCH($E26, acciones_en_combate!$A$11:$A$24, 0),MATCH(J$7, acciones_en_combate!E$11:E$24, 0)+4),"")} | K26: {=ifna(index(acciones_en_combate!$A$11:$F$24,MATCH($E26, acciones_en_combate!$A$11:$A$24, 0),MATCH(K$7, acciones_en_combate!F$11:F$24, 0)+5),"")}
A27: Saving Throw | B27: CON | C27: =datos_basicos!G5+datos_basicos!$D$6*D27 -> 6 | D27: TRUE | F27: FALSE | G27: {=ifna(index(acciones_en_combate!$A$11:$F$24,MATCH($E27, acciones_en_combate!$A$11:$A$24, 0),MATCH(G$7, acciones_en_combate!B$11:B$24, 0)+1),"")} | H27: {=ifna(index(acciones_en_combate!$A$11:$F$24,MATCH($E27, acciones_en_combate!$A$11:$A$24, 0),MATCH(H$7, acciones_en_combate!C$11:C$24, 0)+2),"")} | I27: {=ifna(index(acciones_en_combate!$A$11:$F$24,MATCH($E27, acciones_en_combate!$A$11:$A$24, 0),MATCH(I$7, acciones_en_combate!D$11:D$24, 0)+3),"")} | J27: {=ifna(index(acciones_en_combate!$A$11:$F$24,MATCH($E27, acciones_en_combate!$A$11:$A$24, 0),MATCH(J$7, acciones_en_combate!E$11:E$24, 0)+4),"")} | K27: {=ifna(index(acciones_en_combate!$A$11:$F$24,MATCH($E27, acciones_en_combate!$A$11:$A$24, 0),MATCH(K$7, acciones_en_combate!F$11:F$24, 0)+5),"")}
A28: Saving Throw | B28: INT | C28: =datos_basicos!G6+datos_basicos!$D$6*D28 -> 2 | D28: FALSE | F28: FALSE | G28: {=ifna(index(acciones_en_combate!$A$11:$F$24,MATCH($E28, acciones_en_combate!$A$11:$A$24, 0),MATCH(G$7, acciones_en_combate!B$11:B$24, 0)+1),"")} | H28: {=ifna(index(acciones_en_combate!$A$11:$F$24,MATCH($E28, acciones_en_combate!$A$11:$A$24, 0),MATCH(H$7, acciones_en_combate!C$11:C$24, 0)+2),"")} | I28: {=ifna(index(acciones_en_combate!$A$11:$F$24,MATCH($E28, acciones_en_combate!$A$11:$A$24, 0),MATCH(I$7, acciones_en_combate!D$11:D$24, 0)+3),"")} | J28: {=ifna(index(acciones_en_combate!$A$11:$F$24,MATCH($E28, acciones_en_combate!$A$11:$A$24, 0),MATCH(J$7, acciones_en_combate!E$11:E$24, 0)+4),"")} | K28: {=ifna(index(acciones_en_combate!$A$11:$F$24,MATCH($E28, acciones_en_combate!$A$11:$A$24, 0),MATCH(K$7, acciones_en_combate!F$11:F$24, 0)+5),"")}
A29: Saving Throw | B29: WIS | C29: =datos_basicos!G7+datos_basicos!$D$6*D29 -> 3 | D29: TRUE | F29: FALSE | G29: {=ifna(index(acciones_en_combate!$A$11:$F$24,MATCH($E29, acciones_en_combate!$A$11:$A$24, 0),MATCH(G$7, acciones_en_combate!B$11:B$24, 0)+1),"")} | H29: {=ifna(index(acciones_en_combate!$A$11:$F$24,MATCH($E29, acciones_en_combate!$A$11:$A$24, 0),MATCH(H$7, acciones_en_combate!C$11:C$24, 0)+2),"")} | I29: {=ifna(index(acciones_en_combate!$A$11:$F$24,MATCH($E29, acciones_en_combate!$A$11:$A$24, 0),MATCH(I$7, acciones_en_combate!D$11:D$24, 0)+3),"")} | J29: {=ifna(index(acciones_en_combate!$A$11:$F$24,MATCH($E29, acciones_en_combate!$A$11:$A$24, 0),MATCH(J$7, acciones_en_combate!E$11:E$24, 0)+4),"")} | K29: {=ifna(index(acciones_en_combate!$A$11:$F$24,MATCH($E29, acciones_en_combate!$A$11:$A$24, 0),MATCH(K$7, acciones_en_combate!F$11:F$24, 0)+5),"")}
A30: Saving Throw | B30: CHA | C30: =datos_basicos!G8+datos_basicos!$D$6*D30 -> 5 | D30: TRUE | F30: FALSE | G30: {=ifna(index(acciones_en_combate!$A$11:$F$24,MATCH($E30, acciones_en_combate!$A$11:$A$24, 0),MATCH(G$7, acciones_en_combate!B$11:B$24, 0)+1),"")} | H30: {=ifna(index(acciones_en_combate!$A$11:$F$24,MATCH($E30, acciones_en_combate!$A$11:$A$24, 0),MATCH(H$7, acciones_en_combate!C$11:C$24, 0)+2),"")} | I30: {=ifna(index(acciones_en_combate!$A$11:$F$24,MATCH($E30, acciones_en_combate!$A$11:$A$24, 0),MATCH(I$7, acciones_en_combate!D$11:D$24, 0)+3),"")} | J30: {=ifna(index(acciones_en_combate!$A$11:$F$24,MATCH($E30, acciones_en_combate!$A$11:$A$24, 0),MATCH(J$7, acciones_en_combate!E$11:E$24, 0)+4),"")} | K30: {=ifna(index(acciones_en_combate!$A$11:$F$24,MATCH($E30, acciones_en_combate!$A$11:$A$24, 0),MATCH(K$7, acciones_en_combate!F$11:F$24, 0)+5),"")}

Sheet Hoja1
K1: Raza:
K2: Lenguas:
K3: Edad:
A4: Atributo | C4: Valor | D4: Mod | E4: Salv | F4: Habilidades | I4: Exp | K4: Niveles:
A5: Fuerza | E5: O | F5: O Atletismo | I5: O
A6: Destreza | E6: O | F6: O Acrobacias | I6: O
F7: O Juegos de Manos | I7: O
F8: O Sigilo | I8: O | K8: Proficiencia:
A9: Constitución | E9: O
A10: Inteligencia | E10: O | F10: O Arcano | I10: O | M10: Base | O10: Actual | Q10: Temp
F11: O Historia | I11: O | K11: PV:
F12: O Investigación | I12: O | K12: HD:
F13: O Naturaleza | I13: O | K13: Iniciativa:
F14: O Religión | I14: O | K14: Velocidad:
A15: Sabiduría | E15: O | F15: O Trato con animales | I15: O | K15: Clase de Armadura
F16: O Introspección | I16: O | K16: Total:
F17: O Medicina | I17: O | K17: Armadura:
F18: O Percepción | I18: O | K18: Destreza:
F19: O Supervivencia | I19: O | K19: Escudo:
A20: Carisma | E20: O | F20: O Engaño | I20: O | K20: Otros:
F21: O Intimidación | I21: O
F22: O Performance | I22: O | M22: Oro | O22: Plata | Q22: Cobre
F23: O Persuasión | I23: O | K23: Monedas:
A25: Ataques frecuentes
A26: Arma - Conjuro | D26: Ataque | F26: Daño | H26: Extras
A27: 1.
A28: 2.
A29: 3.
A30: 4.
A32: Lanzamiento de conjuros
A33: Ataque: | F33: Dif:
A34: Slots
A35: 1 | C35: 2 | E35: 3 | G35: 4 | I35: 5 | K35: 6 | M35: 7 | O35: 8 | Q35: 9
A36: Max | B36: Used | C36: Max | D36: Used | E36: Max | F36: Used | G36: Max | H36: Used | I36: Max | J36: Used | K36: Max | L36: Used | M36: Max | N36: Used | O36: Max | P36: Used | Q36: Max | R36: Used
A38: Disponibles
A39: 0 | H39: Mochila | Z39: Fórmulas
H40: Item | K40: Uso | Z40: Valor | AC40: Fórmula
Z41: Modificador Atributo | AC41: PISO((Valor - 10) / 2)
Z42: Salvación Atributo | AC42: Mod (+ Proficiencia)
Z43: Expertise | AC43: Mod + (Proficiencia * 2)
...
